Workbook

Sheet Spotswood College
A2: 1
A3: 1
A4: 1
A5: 1
A6: 1
A7: 1
A8: 1 | B8: Project: | C8: Spotswood College | K8: DK Roofing BOQ
A9: 1 | B9: Location:
C10: Building | D10: Timber | I10: 1
A11: 1 | B11: SN | C11: Description | D11: Type | E11: Girth | F11: Degree | G11: Location | H11: BMT | I11: Coating | J11: Specs | K11: Unit | L11: BOQ | M11: TAKEOFF | Q11: Qty | R11: MATERIAL | V11: LABOUR | AD11: TOTAL COST | AE11: For Markup | AF11: factor | AG11: Prelims | AH11: Margin | AJ11: Rate | AK11: Amount | AM11: Qty | AN11: Quantity Formula | AO11: Discrepancy | AP11: Remarks
A12: 1 | L12: QTY | M12: Qty | N12: Pitch F | O12: 0 | P12: Unit | R12: Rate | S12: Amount | T12: Total Material Cost | U12: Rate | V12: Amount | W12: Total Labour | AF12: =SUM(AF13) -> 0
A13: 1
A14: 1 | C14: ROOFING WORKS
A15: 1 | C15: Roof Sheeting
A16: 1 | C16: Supply and install 4311: DW Dimond advanced roofing system - 0.55mm BMT AM150 Zincalume Dimond BB900 TBC with Thermakraft 407 Covertek Roof Underlay, Dimond Ashgrid AG40 rail and AB40 post located above all purlins complete with EPDM thermal breaks., Dimond R1.8 75mm thermal BIB insulation over R2.4 95mm BIB insulation, Lap seal tape, and 0.55mm BMT Dimond BB900 TBC Zincalume Base Sheet, as per general notes (A002) | L16: =Q16 -> #REF! | Q16: =Q17 -> #REF! | S16: =T16/Q16 -> #REF! | T16: =SUM(S17:S35) -> #REF! | U16: =iferror(if(B16="",,VLOOKUP(B16,Data!$B$2:$F905,5,0)),"") | V16: =W16/Q16 -> #REF! | W16: =SUM(W17:W35) -> #REF! | X16: =W16/$AC$176/$W$183/$X$173 -> #REF! | Y16: =(T16+W16)=(SUM(AB17:AB34)) -> #REF! | Z16: =(T16+W16)-(SUM(AB17:AB34)) -> #REF! | AD16: =W16+T16 -> #REF! | AE16: =AD16 -> #REF! | AF16: =AE16/$AE$151 -> #REF! | AG16: =AF16*$AG$158 -> #REF! | AH16: =AF16*$AG$161 -> #REF! | AJ16: =ROUND(AK16/L16,2) -> #REF! | AK16: =ROUND(AH16+AG16+AD16,2) -> #REF!
B17: DRBB900Zinc055 | C17: 4311:01 - 0.55mm BMT AM150 Zincalume Dimond BB900 TBC @ 9 deg | D17: R-Sheeting | E17: =IFERROR(__xludf.DUMMYFUNCTION("IF($B$17:$B379="""","""", VLOOKUP( $B$17:$B379, QUERY( IMPORTRANGE(""1Ag27m9YF5mMfJh2E6NipJDFvPLlDI1p-s_1XEnzMHcc"",""Merge!F2:R""), ""select Col1, Col11"", 0 ), 2, FALSE ) ) "),"#REF!") -> #REF! | F17: =IFERROR(__xludf.DUMMYFUNCTION("IFERROR(REGEXEXTRACT(C17,""@\s*(\d+)\s*deg"")&""°"","""") "),"9°") -> 9° | H17: =IFERROR(__xludf.DUMMYFUNCTION("IFERROR(REGEXEXTRACT(C17, ""(\d*\.\d+)mm""), """")"),"0.55") -> 0.55 | J17: Specs | K17: m2 | L17: 602.91 | M17: =L17*E17 -> #REF! | N17: =IFERROR(__xludf.DUMMYFUNCTION("ARRAYFORMULA(IF( (B17:B148<>"""") * (F17:F148=""""), 1, IF( F17:F148="""", """", IFERROR(1/COS(RADIANS(REGEXEXTRACT(F17:F148,""(\d+)"")))) ) ))"),1.0124651257880029) -> 1.0124651 | O17: 1 | P17: 1 | Q17: =M17*N17*O17*P17 -> #REF! | R17: {=iferror(if(B17:B148="",,VLOOKUP(B17:B148,Data!$B$2:$K905,9,0)),"")} | S17: =R17*Q17 -> #REF! | U17: {=iferror(if(B17:B148="",,VLOOKUP(B17:B148,Data!$B$2:$K905,10,0)),"")} | W17: =U17*Q17 -> #REF! | X17: =W17/$AC$176/$W$183/Y17 -> #REF! | Y17: 10 | Z17: =Q17/X17 -> #REF! | AA17: =27*15/60/8 -> 0.84375 | AB17: =W17+S17 -> #REF! | AM17: {=IFERROR( IF(B17:B148="","", IF(D17:D148="Rain Head",L17:L148, IF(D17:D148="R-Accessories",L17:L148, IF(D17:D148="R-AdvFixing",L17:L148, IF(D17:D148="R-Angle Bar",L17:L148, IF(D17:D148="R-Butyl",L17:L148/12, IF(D17:D148="R-Comb Filler",L17:L148, IF(D17:D148="R-Dektite",L17:L148, IF(D17:D148="R-Dektite Fix",L17:L148*(ROUNDUP(E17:E148/0.05,0)+1), IF(D17:D148="R-Dektite Seal",L17:L148*(E17:E148/8), IF(D17:D148="R-DP",L17:L148, IF(D17:D148="R-DPC",L17:L148, IF(D17:D148="R-DPBracket",L17:L148, IF(D17:D148="R-EavesGut",L17:L148, IF(D17:D148="R-EGBracket",ROUNDUP(L17:L148/E17:E148,0)+1, IF(D17:D148="R-EGBracketFixing",ROUNDUP(L17:L148*E17:E148,0)+1, IF(D17:D148="R-ExpFoam",L17:L148, IF(D17:D148="R-Fascia",L17:L148, IF(D17:D148="R-FasciaBracket",ROUNDUP(L17:L148/E17:E148,0)+1, IF(D17:D148="R-FasciaBracketFixing",ROUNDUP(L17:L148/0.6,0)+1, IF(D17:D148="R-FFBottom",L17:L148, IF(D17:D148="R-FFSide",L17:L148, IF(D17:D148="R-FFTop",L17:L148, IF(D17:D148="R-Fixings",ROUNDUP(L17:L148*6,0)+1, IF(D17:D148="R-Flashing",L17:L148, IF(D17:D148="R-GenFix",ROUNDUP(L17:L148/0.6,0)+1, IF(D17:D148="R-Insulation",L17:L148, IF(D17:D148="R-KS",VLOOKUP(B17:B148,Data!B2:H905,6,0)*L17:L148, IF(D17:D148="R-KSFixing",ROUNDUP(L17:L148*6,0)+1, IF(D17:D148="R-LM",L17:L148, IF(D17:D148="R-m2",L17:L148*E17:E148, IF(D17:D148="R-OF",L17:L148, IF(D17:D148="R-OP",L17:L148, IF(D17:D148="R-OPFixing",L17:L148*10, IF(D17:D148="R-OPSeal",(L17:L148*3.14*E17:E148)/8, IF(D17:D148="R-PanFlashing",L17:L148, IF(D17:D148="R-PanFlash Fix",ROUNDUP((L17:L148*E17:E148)*8,0)+1, IF(D17:D148="R-Post",L17:L148/E17:E148, IF(D17:D148="R-PostFix",L17:L148, IF(D17:D148="R-Perforated ",ROUNDUP(L17:L148/E17:E148,0), IF(D17:D148="R-PerforatedFix",ROUNDUP(L17:L148*8,0)+1, IF(D17:D148="R-Rail",L17:L148, IF(D17:D148="R-Rainhead",L17:L148, IF(D17:D148="R-Ridge Vent",(L17:L148/(VLOOKUP(B17:B148,Data!B2:H905,6,0))), IF(D17:D148="R-Rivets",ROUNDUP(((L17:L148/5.7)+1)*(E17:E148/0.05),0), IF(D17:D148="R-RivetsEa",L17:L148, IF(D17:D148="R-RoofClips",ROUNDUP(L17:L148/E17:E148,0)+1, IF(D17:D148="R-Safety Mesh",L17:L148, IF(D17:D148="R-Scupper",L17:L148, IF(D17:D148="R-Sheeting",VLOOKUP(B17:B148,Data!B2:H905,6,0)*L17:L148, IF(D17:D148="R-Silicone",(ROUNDDOWN((L17:L148/5.7)+2,0)*E17:E148)/8, IF(D17:D148="R-Silicone LM",L17:L148/8, IF(D17:D148="R-SumpFixing",ROUNDUP((L17:L148*E17:E148)/0.05,0)+1, IF(D17:D148="R-SumpSeal",(L17:L148*E17:E148)/8, IF(D17:D148="R-Sump",L17:L148, IF(D17:D148="R-Takeoff ea",L17:L148, IF(D17:D148="R-Takeoff LM",L17:L148, IF(D17:D148="R-Takeoff m2",L17:L148*E17:E148, IF(D17:D148="R-Takeoff m3",L17:L148*E17:E148*H17:H148, IF(D17:D148="R-Timber ea",ROUNDUP(L17:L148/E17:E148,0)+1, IF(D17:D148="R-Timber LM",L17:L148, IF(D17:D148="R-Timber m2",L17:L148*E17:E148, IF(D17:D148="R-Timber eaFix",L17:L148*E17:E148, IF(D17:D148="R-TimberLMFix",ROUNDUP(L17:L148/1,0)+1, IF(D17:D148="R-Timberm2Fix",ROUNDUP(L17:L148*5,0)+1, IF(D17:D148="R-TopHatFixings",ROUNDUP(L17:L148/0.6,0)*2, IF(D17:D148="R-Trimmer/Packer",L17:L148, IF(D17:D148="R-TS",VLOOKUP(B17:B148,Data!B2:H905,6,0)*L17:L148, IF(D17:D148="R-TSFixing",(ROUNDUP(L17:L148/0.6,0)+1)*2, IF(D17:D148="R-TSLapSeal",L17:L148, IF(D17:D148="R-TSPurlinStrip",L17:L148/E17:E148, IF(D17:D148="R-TSStitching",L17:L148*2, IF(D17:D148="R-TPO",L17:L148, IF(D17:D148="R-TPO Gutter",L17:L148, IF(D17:D148="R-TU/TD",L17:L148, IF(D17:D148="R-UBracket",ROUNDUP(L17:L148/E17:E148,0)+1, IF(D17:D148="R-UBracketFix",ROUNDUP(L17:L148*E17:E148,0)+1, IF(D17:D148="R-Underlay",(L17:L148/(VLOOKUP(B17:B148,Data!B2:H905,6,0)-0.15))*0.15+L17:L148, IF(D17:D148="R-UTape",L17:L148/E17:E148/H17:H148, IF(D17:D148="R-Vent",(L17:L148/(VLOOKUP(B17:B148,Data!B2:H905,6,0))), IF(D17:D148="R-Valley Gutter",L17:L148, IF(D17:D148="R-VapBarrier",(L17:L148/(E17:E148-0.15))*0.15+L17:L148, IF(D17:D148="R-Washer",L17:L148, IF(D17:D148="R-ZFlashingFix",(L17:L148/E17:E148)*2, IF(D17:D148="W-Comb Filler",L17:L148, IF(D17:D148="W-DPC",L17:L148, IF(D17:D148="W-Fixings",ROUNDUP(L17:L148*6,0)+1, IF(D17:D148="W-Flashing",L17:L148, IF(D17:D148="W-GenFix",ROUNDUP(L17:L148/0.6,0)+1, IF(D17:D148="W-KS",VLOOKUP(B17:B148,Data!B2:H905,6,0)*L17:L148, IF(D17:D148="W-KSFixing",ROUNDUP(L17:L148*6,0)+1, IF(D17:D148="W-RAB",L17:L148, IF(D17:D148="W-RABFix",ROUNDUP(L17:L148*E17:E148,0)+1, IF(D17:D148="W-Rivets",ROUNDUP(((L17:L148/5.7)+1)*(E17:E148/0.05),0), IF(D17:D148="W-Silicone",(ROUNDDOWN((L17:L148/5.7)+2,0)*E17:E148)/8, IF(D17:D148="W-Silicone LM",L17:L148/8, IF(D17:D148="W-Sheeting",VLOOKUP(B17:B148,Data!B2:H905,6,0)*L17:L148, IF(D17:D148="W-Silicone",(ROUNDDOWN((L17:L148/5.7)+2,0)*E17:E148)/8, IF(D17:D148="W-Silicone LM",L17:L148/8, IF(D17:D148="W-Takeoff ea",L17:L148, IF(D17:D148="W-Takeoff LM",L17:L148, IF(D17:D148="W-Takeoff m2",L17:L148*E17:E148, IF(D17:D148="W-Timber LM",L17:L148, IF(D17:D148="W-Timber m2",L17:L148*E17:E148, IF(D17:D148="W-TimberLMFix",ROUNDUP(L17:L148/1,0)+1, IF(D17:D148="W-Timberm2Fix",ROUNDUP(L17:L148*5,0)+1, IF(D17:D148="W-TopHatFixings",ROUNDUP(L17:L148/0.6,0)*2, IF(D17:D148="W-Trimmer/Packer",L17:L148, IF(D17:D148="W-TimberLMFix",ROUNDUP(L17:L148/0.6,0)+1, IF(D17:D148="W-Timberm2Fix",ROUNDUP(L17:L148*8,0)+1, IF(D17:D148="W-Underlay",(L17:L148/(VLOOKUP(B17:B148,Data!B2:H905,6,0)-0.15))*0.15+L17:L148, IF(D17:D148="W-UTape",L17:L148/E17:E148/H17:H148, IF(D17:D148="W-Vent",(L17:L148/(VLOOKUP(B17:B148,Data!B2:H905,6,0))), 0 ))))))))))))))))))))))))))))))))))))))))))))))))))))))))))))))))))))))))))))))))))))))))))))))))))))))))))))))))), "" )} | AN17: {=if(B17:B148="",,if(M17:M148=AM17:AM148,"Matched","Mismatched"))} -> #REF! | AO17: {=if(AM17:AM148="","",AM17:AM148-M17:M148)}
N18: =IFERROR(__xludf.DUMMYFUNCTION("""COMPUTED_VALUE"""),"") | AB18: =W18+S18 -> 0
B19: DR75mmInsul | C19: Dimond R1.8 75mm thermal BIB insulation | D19: R-Insulation | F19: =F59 -> 9° | J19: Specs | K19: m2 | L19: 539.5 | M19: =L19 -> 539.5 | N19: =IFERROR(__xludf.DUMMYFUNCTION("""COMPUTED_VALUE"""),1.0124651257880029) -> 1.0124651 | O19: 1 | P19: 1 | Q19: =M19*N19*O19*P19 -> 546.22494 | S19: =R19*Q19 -> 0 | W19: =U19*Q19 -> 0 | AB19: =W19+S19 -> 0 | AM19: 539.5 | AN19: Matched | AO19: 0
B20: DR95mmInsul | C20: Dimond R2.4 95mm BIB insulation | D20: R-Insulation | F20: =F19 -> 9° | J20: Specs | K20: m2 | L20: =M19 -> 539.5 | M20: =L20 -> 539.5 | N20: =IFERROR(__xludf.DUMMYFUNCTION("""COMPUTED_VALUE"""),1.0124651257880029) -> 1.0124651 | O20: 1 | P20: 1 | Q20: =M20*N20*O20*P20 -> 546.22494 | S20: =R20*Q20 -> 0 | W20: =U20*Q20 -> 0 | AB20: =W20+S20 -> 0 | AM20: 539.5 | AN20: Matched | AO20: 0
N21: =IFERROR(__xludf.DUMMYFUNCTION("""COMPUTED_VALUE"""),"") | AB21: =W21+S21 -> 0
B22: DARSFixSt12x75 | C22: Top Sheet Fixing - STEEL 12X75 COLOUR X100 | D22: R-AdvFixing | F22: =F17 -> 9° | H22: =IFERROR(__xludf.DUMMYFUNCTION("IFERROR(REGEXEXTRACT(C22, ""(\d*\.\d+)mm""), """")"),"") | J22: Specs | K22: ea | L22: =M28 -> 676.68 | M22: 676.68 | N22: =IFERROR(__xludf.DUMMYFUNCTION("""COMPUTED_VALUE"""),1.0124651257880029) -> 1.0124651 | O22: 1 | P22: 1 | Q22: =M22*N22*O22*P22 -> 685.1149 | S22: =R22*Q22 -> 0 | W22: =U22*Q22 -> 0 | AB22: =W22+S22 -> 0 | AM22: 676.68 | AN22: Matched | AO22: 0
B23: DARSepdmWsh | C23: Top Sheet EPDM - EPDM SEALING WASH X100 | D23: R-AdvFixing | F23: =F22 -> 9° | J23: Specs | K23: LM | L23: =M28 -> 676.68 | M23: 676.68 | N23: =IFERROR(__xludf.DUMMYFUNCTION("""COMPUTED_VALUE"""),1.0124651257880029) -> 1.0124651 | AB23: =W23+S23 -> 0 | AM23: 676.68 | AN23: Matched | AO23: 0
B24: DARSPrWshrBB900 | C24: Top Sheet Profile Washer - ROOF WASHER BB900 x100 | D24: R-AdvFixing | F24: =F23 -> 9° | J24: Specs | K24: ea | L24: =M28 -> 676.68 | M24: 676.68 | N24: =IFERROR(__xludf.DUMMYFUNCTION("""COMPUTED_VALUE"""),1.0124651257880029) -> 1.0124651 | AB24: =W24+S24 -> 0 | AM24: 676.68 | AN24: Matched | AO24: 0
N25: =IFERROR(__xludf.DUMMYFUNCTION("""COMPUTED_VALUE"""),"") | AB25: =W25+S25 -> 0
B26: AG40rail | C26: 4311:03 - Ashgrid AG40 rail | D26: R-Rail | J26: Specs | K26: LM | L26: 676.68 | M26: 676.68 | N26: =IFERROR(__xludf.DUMMYFUNCTION("""COMPUTED_VALUE"""),1.0) -> 1 | O26: 1 | P26: 1 | Q26: =M26*N26*O26*P26 -> 676.68 | S26: =R26*Q26 -> 0 | W26: =U26*Q26 -> 0 | AB26: =W26+S26 -> 0 | AM26: 676.68 | AN26: Matched | AO26: 0
N27: =IFERROR(__xludf.DUMMYFUNCTION("""COMPUTED_VALUE"""),"") | AB27: =W27+S27 -> 0
B28: AB40post | C28: 4311:03 - AB40 post | D28: R-Post | E28: 1 | J28: Specs | K28: ea | L28: =M26 -> 676.68 | M28: =L28/E28 -> 676.68 | N28: =IFERROR(__xludf.DUMMYFUNCTION("""COMPUTED_VALUE"""),1.0) -> 1 | O28: 1 | P28: 1 | Q28: =M28*N28*O28*P28 -> 676.68 | S28: =R28*Q28 -> 0 | W28: =U28*Q28 -> 0 | AB28: =W28+S28 -> 0 | AM28: 676.68 | AN28: Matched | AO28: 0
B29: PostFixSt12x30 | C29: 4311:11 - Fixings 12g x 20mm tek (for steel purlins) to secure the post to purlins. STEEL 12X30 NO NEO X100 | D29: R-PostFix | J29: Specs | K29: ea | L29: =M28 -> 676.68 | M29: 676.68 | N29: =IFERROR(__xludf.DUMMYFUNCTION("""COMPUTED_VALUE"""),1.0) -> 1 | O29: 1 | P29: 2 | Q29: =M29*N29*O29*P29 -> 1353.36 | S29: =R29*Q29 -> 0 | W29: =U29*Q29 -> 0 | AB29: =W29+S29 -> 0 | AM29: 676.68 | AN29: Matched | AO29: 0
N30: =IFERROR(__xludf.DUMMYFUNCTION("""COMPUTED_VALUE"""),"") | AB30: =W30+S30 -> 0
B31: EPDMThrmBrks | C31: 4311:03 - EPDM thermal breaks | D31: R-Takeoff LM | J31: Specs | K31: LM | L31: =M26 -> 676.68 | M31: =L31 -> 676.68 | N31: =IFERROR(__xludf.DUMMYFUNCTION("""COMPUTED_VALUE"""),1.0) -> 1 | O31: 1 | P31: 1 | Q31: =M31*N31*O31*P31 -> 676.68 | S31: =R31*Q31 -> 0 | W31: =U31*Q31 -> 0 | AB31: =W31+S31 -> 0 | AM31: 676.68 | AN31: Matched | AO31: 0
N32: =IFERROR(__xludf.DUMMYFUNCTION("""COMPUTED_VALUE"""),"") | AB32: =W32+S32 -> 0
B33: DRBB900Maxam055 | C33: 4311:01 - 0.55bmt BB900 Maxam | D33: R-Sheeting | E33: =IFERROR(__xludf.DUMMYFUNCTION("IF($B$17:$B379="""","""", VLOOKUP( $B$17:$B379, QUERY( IMPORTRANGE(""1Ag27m9YF5mMfJh2E6NipJDFvPLlDI1p-s_1XEnzMHcc"",""Merge!F2:R""), ""select Col1, Col11"", 0 ), 2, FALSE ) ) "),"#REF!") -> #REF! | F33: 9° | H33: 0.55 | J33: Specs | K33: m2 | L33: =L17 -> 602.91 | M33: =L33*E33 -> #REF! | N33: =IFERROR(__xludf.DUMMYFUNCTION("""COMPUTED_VALUE"""),1.0124651257880029) -> 1.0124651 | O33: 1 | P33: 1 | Q33: =M33*N33*O33*P33 -> #REF! | S33: =R33*Q33 -> #REF! | W33: =U33*Q33 -> #REF! | AB33: =W33+S33 -> #REF! | AN33: #REF!
B34: LinerFixSt12x20 | C34: Liner Fixing - STEEL 12X20 PER X100 | J34: Specs | K34: ea | L34: 676.68 | M34: 676.68 | N34: =IFERROR(__xludf.DUMMYFUNCTION("""COMPUTED_VALUE"""),1.0) -> 1 | O34: 1 | P34: 1 | Q34: =M34*N34*O34*P34 -> 676.68 | S34: =R34*Q34 -> 0 | W34: =U34*Q34 -> 0 | AB34: =W34+S34 -> 0 | AM34: 0 | AN34: Mismatched | AO34: -676.68
N35: =IFERROR(__xludf.DUMMYFUNCTION("""COMPUTED_VALUE"""),"")
A36: 1 | C36: Supply and install 4311: DW Dimond advanced roofing system - 0.55mm BMT AM150 Zincalume Dimond BB900 TBC with Thermakraft 407 Covertek Roof Underlay, Dimond Ashgrid AG40 rail and AB40 post located above all purlins complete with EPDM thermal breaks., Dimond R1.8 75mm thermal BIB insulation over R2.4 95mm BIB insulation, Lap seal tape, and 0.55mm BMT Dimond BB900 TBC Zincalume Base Sheet, as per general notes (A002) | L36: =Q36 -> #REF! | N36: =IFERROR(__xludf.DUMMYFUNCTION("""COMPUTED_VALUE"""),"") | Q36: =Q37 -> #REF! | S36: =T36/Q36 -> #REF! | T36: =SUM(S37:S55) -> #REF! | V36: =W36/Q36 -> #REF! | W36: =SUM(W37:W55) -> #REF! | X36: =W36/$AC$176/$W$183/$X$173 -> #REF! | Y36: =(T36+W36)=(SUM(AB37:AB55)) -> #REF! | Z36: =(T36+W36)-(SUM(AB37:AB55)) -> #REF! | AD36: =W36+T36 -> #REF! | AE36: =AD36 -> #REF! | AF36: =AE36/$AE$151 -> #REF! | AG36: =AF36*$AG$158 -> #REF! | AH36: =AF36*$AG$161 -> #REF! | AJ36: =ROUND(AK36/L36,2) -> #REF! | AK36: =ROUND(AH36+AG36+AD36,2) -> #REF!
B37: DRBB900Zinc055 | C37: 4311:01 - 0.55mm BMT AM150 Zincalume Dimond BB900 TBC @ 5 deg | D37: R-Sheeting | E37: =IFERROR(__xludf.DUMMYFUNCTION("IF($B$17:$B379="""","""", VLOOKUP( $B$17:$B379, QUERY( IMPORTRANGE(""1Ag27m9YF5mMfJh2E6NipJDFvPLlDI1p-s_1XEnzMHcc"",""Merge!F2:R""), ""select Col1, Col11"", 0 ), 2, FALSE ) ) "),"#REF!") -> #REF! | F37: =IFERROR(__xludf.DUMMYFUNCTION("IFERROR(REGEXEXTRACT(C37,""@\s*(\d+)\s*deg"")&""°"","""") "),"5°") -> 5° | H37: =IFERROR(__xludf.DUMMYFUNCTION("IFERROR(REGEXEXTRACT(C37, ""(\d*\.\d+)mm""), """")"),"0.55") -> 0.55 | J37: Specs | K37: m2 | L37: 1029.42 | M37: =L37*E37 -> #REF! | N37: =IFERROR(__xludf.DUMMYFUNCTION("""COMPUTED_VALUE"""),1.0038198375433474) -> 1.0038198 | O37: 1 | P37: 1 | Q37: =M37*N37*O37*P37 -> #REF! | S37: =R37*Q37 -> #REF! | W37: =U37*Q37 -> #REF! | X37: =W37/$AC$176/$W$183/Y37 -> #REF! | Y37: 10 | Z37: =Q37/X37 -> #REF! | AA37: =27*15/60/8 -> 0.84375 | AB37: =W37+S37 -> #REF! | AN37: #REF!
N38: =IFERROR(__xludf.DUMMYFUNCTION("""COMPUTED_VALUE"""),"") | AB38: =W38+S38 -> 0
B39: DR75mmInsul | C39: Dimond R1.8 75mm thermal BIB insulation | D39: R-Insulation | F39: =F61 -> 5° | J39: Specs | K39: m2 | L39: 921.66 | M39: 921.66 | N39: =IFERROR(__xludf.DUMMYFUNCTION("""COMPUTED_VALUE"""),1.0038198375433474) -> 1.0038198 | O39: 1 | P39: 1 | Q39: =M39*N39*O39*P39 -> 925.18059 | S39: =R39*Q39 -> 0 | W39: =U39*Q39 -> 0 | AB39: =W39+S39 -> 0 | AM39: 921.66 | AN39: Matched | AO39: 0
B40: DR95mmInsul | C40: Dimond R2.4 95mm BIB insulation | D40: R-Insulation | F40: =F39 -> 5° | J40: Specs | K40: m2 | L40: =M39 -> 921.66 | M40: 921.66 | N40: =IFERROR(__xludf.DUMMYFUNCTION("""COMPUTED_VALUE"""),1.0038198375433474) -> 1.0038198 | O40: 1 | P40: 1 | Q40: =M40*N40*O40*P40 -> 925.18059 | S40: =R40*Q40 -> 0 | W40: =U40*Q40 -> 0 | AB40: =W40+S40 -> 0 | AM40: 921.66 | AN40: Matched | AO40: 0
N41: =IFERROR(__xludf.DUMMYFUNCTION("""COMPUTED_VALUE"""),"") | AB41: =W41+S41 -> 0
...

Sheet New Spotswood College
A2: 1
A3: 1
A4: 1
A5: 1
A6: 1
A7: 1
A8: 1 | B8: Project: | C8: Spotswood College | K8: DK Roofing BOQ
A9: 1 | B9: Location:
C10: Building | D10: Timber | I10: 1
A11: 1 | B11: SN | C11: Description | D11: Type | E11: Girth | F11: Degree | G11: Location | H11: BMT | I11: Coating | J11: Specs | K11: Unit | L11: BOQ | M11: TAKEOFF | Q11: Qty | R11: MATERIAL | V11: LABOUR | AD11: TOTAL COST | AE11: For Markup | AF11: factor | AG11: Prelims | AH11: Margin | AJ11: Rate | AK11: Amount | AM11: Qty | AN11: Quantity Formula | AO11: Discrepancy | AP11: Remarks
A12: 1 | L12: QTY | M12: Qty | N12: Pitch F | O12: 0 | P12: Unit | R12: Rate | S12: Amount | T12: Total Material Cost | U12: Rate | V12: Amount | W12: Total Labour | AF12: =SUM(AF13) -> 0
A13: 1
A14: 1 | C14: ROOFING WORKS
A15: 1 | C15: Roof Sheeting
A16: 1 | C16: Supply and install 4311: DW Dimond advanced roofing system - 0.55mm BMT AM150 Zincalume Dimond BB900 TBC with Thermakraft 407 Covertek Roof Underlay, Dimond Ashgrid AG40 rail and AB40 post located above all purlins complete with EPDM thermal breaks., Dimond R1.8 75mm thermal BIB insulation over R2.4 95mm BIB insulation, Lap seal tape, and 0.55mm BMT Dimond BB900 TBC Zincalume Base Sheet, as per general notes (A002) | L16: =Q16 -> #REF! | Q16: =Q17 -> #REF! | S16: =T16/Q16 -> #REF! | T16: =SUM(S17:S35) -> #REF! | U16: =iferror(if(B16="",,VLOOKUP(B16,Data!$B$2:$F905,5,0)),"") | V16: =W16/Q16 -> #REF! | W16: =SUM(W17:W35) -> #REF! | X16: =W16/$AC$176/$W$183/$X$173 -> #REF! | Y16: =(T16+W16)=(SUM(AB17:AB34)) -> #REF! | Z16: =(T16+W16)-(SUM(AB17:AB34)) -> #REF! | AD16: =W16+T16 -> #REF! | AE16: =AD16 -> #REF! | AF16: =AE16/$AE$151 -> #REF! | AG16: =AF16*$AG$158 -> #REF! | AH16: =AF16*$AG$161 -> #REF! | AJ16: =ROUND(AK16/L16,2) -> #REF! | AK16: =ROUND(AH16+AG16+AD16,2) -> #REF!
B17: DRBB900Zinc055 | C17: 4311:01 - 0.55mm BMT AM150 Zincalume Dimond BB900 TBC @ 9 deg | D17: R-Sheeting | E17: =IFERROR(__xludf.DUMMYFUNCTION("IF($B$17:$B386="""","""", VLOOKUP( $B$17:$B386, QUERY( IMPORTRANGE(""1Ag27m9YF5mMfJh2E6NipJDFvPLlDI1p-s_1XEnzMHcc"",""Merge!F2:R""), ""select Col1, Col11"", 0 ), 2, FALSE ) ) "),"#REF!") -> #REF! | F17: =IFERROR(__xludf.DUMMYFUNCTION("IFERROR(REGEXEXTRACT(C17,""@\s*(\d+)\s*deg"")&""°"","""") "),"9°") -> 9° | H17: =IFERROR(__xludf.DUMMYFUNCTION("IFERROR(REGEXEXTRACT(C17, ""(\d*\.\d+)mm""), """")"),"0.55") -> 0.55 | J17: Specs | K17: m2 | L17: 602.91 | M17: =L17*E17 -> #REF! | N17: =IFERROR(__xludf.DUMMYFUNCTION("ARRAYFORMULA(IF( (B17:B148<>"""") * (F17:F148=""""), 1, IF( F17:F148="""", """", IFERROR(1/COS(RADIANS(REGEXEXTRACT(F17:F148,""(\d+)"")))) ) ))"),1.0124651257880029) -> 1.0124651 | O17: 1 | P17: 1 | Q17: =M17*N17*O17*P17 -> #REF! | R17: {=iferror(if(B17:B148="",,VLOOKUP(B17:B148,Data!$B$2:$K905,9,0)),"")} | S17: =R17*Q17 -> #REF! | U17: {=iferror(if(B17:B148="",,VLOOKUP(B17:B148,Data!$B$2:$K905,10,0)),"")} | W17: =U17*Q17 -> #REF! | X17: =W17/$AC$176/$W$183/Y17 -> #REF! | Y17: 10 | Z17: =Q17/X17 -> #REF! | AA17: =27*15/60/8 -> 0.84375 | AB17: =W17+S17 -> #REF! | AM17: {=IFERROR( IF(B17:B148="","", IF(D17:D148="Rain Head",L17:L148, IF(D17:D148="R-Accessories",L17:L148, IF(D17:D148="R-AdvFixing",L17:L148, IF(D17:D148="R-Angle Bar",L17:L148, IF(D17:D148="R-Butyl",L17:L148/12, IF(D17:D148="R-Comb Filler",L17:L148, IF(D17:D148="R-Dektite",L17:L148, IF(D17:D148="R-Dektite Fix",L17:L148*(ROUNDUP(E17:E148/0.05,0)+1), IF(D17:D148="R-Dektite Seal",L17:L148*(E17:E148/8), IF(D17:D148="R-DP",L17:L148, IF(D17:D148="R-DPC",L17:L148, IF(D17:D148="R-DPBracket",L17:L148, IF(D17:D148="R-EavesGut",L17:L148, IF(D17:D148="R-EGBracket",ROUNDUP(L17:L148/E17:E148,0)+1, IF(D17:D148="R-EGBracketFixing",ROUNDUP(L17:L148*E17:E148,0)+1, IF(D17:D148="R-ExpFoam",L17:L148, IF(D17:D148="R-Fascia",L17:L148, IF(D17:D148="R-FasciaBracket",ROUNDUP(L17:L148/E17:E148,0)+1, IF(D17:D148="R-FasciaBracketFixing",ROUNDUP(L17:L148/0.6,0)+1, IF(D17:D148="R-FFBottom",L17:L148, IF(D17:D148="R-FFSide",L17:L148, IF(D17:D148="R-FFTop",L17:L148, IF(D17:D148="R-Fixings",ROUNDUP(L17:L148*6,0)+1, IF(D17:D148="R-Flashing",L17:L148, IF(D17:D148="R-GenFix",ROUNDUP(L17:L148/0.6,0)+1, IF(D17:D148="R-Insulation",L17:L148, IF(D17:D148="R-KS",VLOOKUP(B17:B148,Data!B2:H905,6,0)*L17:L148, IF(D17:D148="R-KSFixing",ROUNDUP(L17:L148*6,0)+1, IF(D17:D148="R-LM",L17:L148, IF(D17:D148="R-m2",L17:L148*E17:E148, IF(D17:D148="R-OF",L17:L148, IF(D17:D148="R-OP",L17:L148, IF(D17:D148="R-OPFixing",L17:L148*10, IF(D17:D148="R-OPSeal",(L17:L148*3.14*E17:E148)/8, IF(D17:D148="R-PanFlashing",L17:L148, IF(D17:D148="R-PanFlash Fix",ROUNDUP((L17:L148*E17:E148)*8,0)+1, IF(D17:D148="R-Post",L17:L148/E17:E148, IF(D17:D148="R-PostFix",L17:L148, IF(D17:D148="R-Perforated ",ROUNDUP(L17:L148/E17:E148,0), IF(D17:D148="R-PerforatedFix",ROUNDUP(L17:L148*8,0)+1, IF(D17:D148="R-Rail",L17:L148, IF(D17:D148="R-Rainhead",L17:L148, IF(D17:D148="R-Ridge Vent",(L17:L148/(VLOOKUP(B17:B148,Data!B2:H905,6,0))), IF(D17:D148="R-Rivets",ROUNDUP(((L17:L148/5.7)+1)*(E17:E148/0.05),0), IF(D17:D148="R-RivetsEa",L17:L148, IF(D17:D148="R-RoofClips",ROUNDUP(L17:L148/E17:E148,0)+1, IF(D17:D148="R-Safety Mesh",L17:L148, IF(D17:D148="R-Scupper",L17:L148, IF(D17:D148="R-Sheeting",VLOOKUP(B17:B148,Data!B2:H905,6,0)*L17:L148, IF(D17:D148="R-Silicone",(ROUNDDOWN((L17:L148/5.7)+2,0)*E17:E148)/8, IF(D17:D148="R-Silicone LM",L17:L148/8, IF(D17:D148="R-SumpFixing",ROUNDUP((L17:L148*E17:E148)/0.05,0)+1, IF(D17:D148="R-SumpSeal",(L17:L148*E17:E148)/8, IF(D17:D148="R-Sump",L17:L148, IF(D17:D148="R-Takeoff ea",L17:L148, IF(D17:D148="R-Takeoff LM",L17:L148, IF(D17:D148="R-Takeoff m2",L17:L148*E17:E148, IF(D17:D148="R-Takeoff m3",L17:L148*E17:E148*H17:H148, IF(D17:D148="R-Timber ea",ROUNDUP(L17:L148/E17:E148,0)+1, IF(D17:D148="R-Timber LM",L17:L148, IF(D17:D148="R-Timber m2",L17:L148*E17:E148, IF(D17:D148="R-Timber eaFix",L17:L148*E17:E148, IF(D17:D148="R-TimberLMFix",ROUNDUP(L17:L148/1,0)+1, IF(D17:D148="R-Timberm2Fix",ROUNDUP(L17:L148*5,0)+1, IF(D17:D148="R-TopHatFixings",ROUNDUP(L17:L148/0.6,0)*2, IF(D17:D148="R-Trimmer/Packer",L17:L148, IF(D17:D148="R-TS",VLOOKUP(B17:B148,Data!B2:H905,6,0)*L17:L148, IF(D17:D148="R-TSFixing",(ROUNDUP(L17:L148/0.6,0)+1)*2, IF(D17:D148="R-TSLapSeal",L17:L148, IF(D17:D148="R-TSPurlinStrip",L17:L148/E17:E148, IF(D17:D148="R-TSStitching",L17:L148*2, IF(D17:D148="R-TPO",L17:L148, IF(D17:D148="R-TPO Gutter",L17:L148, IF(D17:D148="R-TU/TD",L17:L148, IF(D17:D148="R-UBracket",ROUNDUP(L17:L148/E17:E148,0)+1, IF(D17:D148="R-UBracketFix",ROUNDUP(L17:L148*E17:E148,0)+1, IF(D17:D148="R-Underlay",(L17:L148/(VLOOKUP(B17:B148,Data!B2:H905,6,0)-0.15))*0.15+L17:L148, IF(D17:D148="R-UTape",L17:L148/E17:E148/H17:H148, IF(D17:D148="R-Vent",(L17:L148/(VLOOKUP(B17:B148,Data!B2:H905,6,0))), IF(D17:D148="R-Valley Gutter",L17:L148, IF(D17:D148="R-VapBarrier",(L17:L148/(E17:E148-0.15))*0.15+L17:L148, IF(D17:D148="R-Washer",L17:L148, IF(D17:D148="R-ZFlashingFix",(L17:L148/E17:E148)*2, IF(D17:D148="W-Comb Filler",L17:L148, IF(D17:D148="W-DPC",L17:L148, IF(D17:D148="W-Fixings",ROUNDUP(L17:L148*6,0)+1, IF(D17:D148="W-Flashing",L17:L148, IF(D17:D148="W-GenFix",ROUNDUP(L17:L148/0.6,0)+1, IF(D17:D148="W-KS",VLOOKUP(B17:B148,Data!B2:H905,6,0)*L17:L148, IF(D17:D148="W-KSFixing",ROUNDUP(L17:L148*6,0)+1, IF(D17:D148="W-RAB",L17:L148, IF(D17:D148="W-RABFix",ROUNDUP(L17:L148*E17:E148,0)+1, IF(D17:D148="W-Rivets",ROUNDUP(((L17:L148/5.7)+1)*(E17:E148/0.05),0), IF(D17:D148="W-Silicone",(ROUNDDOWN((L17:L148/5.7)+2,0)*E17:E148)/8, IF(D17:D148="W-Silicone LM",L17:L148/8, IF(D17:D148="W-Sheeting",VLOOKUP(B17:B148,Data!B2:H905,6,0)*L17:L148, IF(D17:D148="W-Silicone",(ROUNDDOWN((L17:L148/5.7)+2,0)*E17:E148)/8, IF(D17:D148="W-Silicone LM",L17:L148/8, IF(D17:D148="W-Takeoff ea",L17:L148, IF(D17:D148="W-Takeoff LM",L17:L148, IF(D17:D148="W-Takeoff m2",L17:L148*E17:E148, IF(D17:D148="W-Timber LM",L17:L148, IF(D17:D148="W-Timber m2",L17:L148*E17:E148, IF(D17:D148="W-TimberLMFix",ROUNDUP(L17:L148/1,0)+1, IF(D17:D148="W-Timberm2Fix",ROUNDUP(L17:L148*5,0)+1, IF(D17:D148="W-TopHatFixings",ROUNDUP(L17:L148/0.6,0)*2, IF(D17:D148="W-Trimmer/Packer",L17:L148, IF(D17:D148="W-TimberLMFix",ROUNDUP(L17:L148/0.6,0)+1, IF(D17:D148="W-Timberm2Fix",ROUNDUP(L17:L148*8,0)+1, IF(D17:D148="W-Underlay",(L17:L148/(VLOOKUP(B17:B148,Data!B2:H905,6,0)-0.15))*0.15+L17:L148, IF(D17:D148="W-UTape",L17:L148/E17:E148/H17:H148, IF(D17:D148="W-Vent",(L17:L148/(VLOOKUP(B17:B148,Data!B2:H905,6,0))), 0 ))))))))))))))))))))))))))))))))))))))))))))))))))))))))))))))))))))))))))))))))))))))))))))))))))))))))))))))))), "" )} | AN17: {=if(B17:B148="",,if(M17:M148=AM17:AM148,"Matched","Mismatched"))} -> #REF! | AO17: {=if(AM17:AM148="","",AM17:AM148-M17:M148)}
N18: =IFERROR(__xludf.DUMMYFUNCTION("""COMPUTED_VALUE"""),"") | AB18: =W18+S18 -> 0
B19: DR75mmInsul | C19: Dimond R1.8 75mm thermal BIB insulation | D19: R-Insulation | F19: =F59 -> 9° | I19: =Q19+Q39 -> 1471.4055 | J19: Specs | K19: m2 | L19: 539.5 | M19: =L19 -> 539.5 | N19: =IFERROR(__xludf.DUMMYFUNCTION("""COMPUTED_VALUE"""),1.0124651257880029) -> 1.0124651 | O19: 1 | P19: 1 | Q19: =M19*N19*O19*P19 -> 546.22494 | S19: =R19*Q19 -> 0 | W19: =U19*Q19 -> 0 | AB19: =W19+S19 -> 0 | AM19: 539.5 | AN19: Matched | AO19: 0
B20: DR95mmInsul | C20: Dimond R2.4 95mm BIB insulation | D20: R-Insulation | F20: =F19 -> 9° | I20: =Q20+Q40 -> 1471.4055 | J20: Specs | K20: m2 | L20: =M19 -> 539.5 | M20: =L20 -> 539.5 | N20: =IFERROR(__xludf.DUMMYFUNCTION("""COMPUTED_VALUE"""),1.0124651257880029) -> 1.0124651 | O20: 1 | P20: 1 | Q20: =M20*N20*O20*P20 -> 546.22494 | S20: =R20*Q20 -> 0 | W20: =U20*Q20 -> 0 | AB20: =W20+S20 -> 0 | AM20: 539.5 | AN20: Matched | AO20: 0
N21: =IFERROR(__xludf.DUMMYFUNCTION("""COMPUTED_VALUE"""),"") | AB21: =W21+S21 -> 0
B22: DARSFixSt12x75 | C22: Top Sheet Fixing - STEEL 12X75 COLOUR X100 | D22: R-AdvFixing | F22: =F17 -> 9° | H22: =IFERROR(__xludf.DUMMYFUNCTION("IFERROR(REGEXEXTRACT(C22, ""(\d*\.\d+)mm""), """")"),"") | J22: Specs | K22: ea | L22: =M28 -> 676.68 | M22: 676.68 | N22: =IFERROR(__xludf.DUMMYFUNCTION("""COMPUTED_VALUE"""),1.0124651257880029) -> 1.0124651 | O22: 1 | P22: 1 | Q22: =M22*N22*O22*P22 -> 685.1149 | S22: =R22*Q22 -> 0 | W22: =U22*Q22 -> 0 | AB22: =W22+S22 -> 0 | AM22: 676.68 | AN22: Matched | AO22: 0
B23: DARSepdmWsh | C23: Top Sheet EPDM - EPDM SEALING WASH X100 | D23: R-AdvFixing | F23: =F22 -> 9° | J23: Specs | K23: LM | L23: =M28 -> 676.68 | M23: 676.68 | N23: =IFERROR(__xludf.DUMMYFUNCTION("""COMPUTED_VALUE"""),1.0124651257880029) -> 1.0124651 | AB23: =W23+S23 -> 0 | AM23: 676.68 | AN23: Matched | AO23: 0
B24: DARSPrWshrBB900 | C24: Top Sheet Profile Washer - ROOF WASHER BB900 x100 | D24: R-AdvFixing | F24: =F23 -> 9° | J24: Specs | K24: ea | L24: =M28 -> 676.68 | M24: 676.68 | N24: =IFERROR(__xludf.DUMMYFUNCTION("""COMPUTED_VALUE"""),1.0124651257880029) -> 1.0124651 | AB24: =W24+S24 -> 0 | AM24: 676.68 | AN24: Matched | AO24: 0
N25: =IFERROR(__xludf.DUMMYFUNCTION("""COMPUTED_VALUE"""),"") | AB25: =W25+S25 -> 0
B26: AG40rail | C26: 4311:03 - Ashgrid AG40 rail | D26: R-Rail | J26: Specs | K26: LM | L26: 676.68 | M26: 676.68 | N26: =IFERROR(__xludf.DUMMYFUNCTION("""COMPUTED_VALUE"""),1.0) -> 1 | O26: 1 | P26: 1 | Q26: =M26*N26*O26*P26 -> 676.68 | S26: =R26*Q26 -> 0 | W26: =U26*Q26 -> 0 | AB26: =W26+S26 -> 0 | AM26: 676.68 | AN26: Matched | AO26: 0
N27: =IFERROR(__xludf.DUMMYFUNCTION("""COMPUTED_VALUE"""),"") | AB27: =W27+S27 -> 0
B28: AB40post | C28: 4311:03 - AB40 post | D28: R-Post | E28: 1 | I28: =L28+L48 -> 1748.09 | J28: Specs | K28: ea | L28: =M26 -> 676.68 | M28: =L28/E28 -> 676.68 | N28: =IFERROR(__xludf.DUMMYFUNCTION("""COMPUTED_VALUE"""),1.0) -> 1 | O28: 1 | P28: 1 | Q28: =M28*N28*O28*P28 -> 676.68 | S28: =R28*Q28 -> 0 | W28: =U28*Q28 -> 0 | AB28: =W28+S28 -> 0 | AM28: 676.68 | AN28: Matched | AO28: 0
B29: PostFixSt12x30 | C29: 4311:11 - Fixings 12g x 20mm tek (for steel purlins) to secure the post to purlins. STEEL 12X30 NO NEO X100 | D29: R-PostFix | J29: Specs | K29: ea | L29: =M28 -> 676.68 | M29: 676.68 | N29: =IFERROR(__xludf.DUMMYFUNCTION("""COMPUTED_VALUE"""),1.0) -> 1 | O29: 1 | P29: 2 | Q29: =M29*N29*O29*P29 -> 1353.36 | S29: =R29*Q29 -> 0 | W29: =U29*Q29 -> 0 | AB29: =W29+S29 -> 0 | AM29: 676.68 | AN29: Matched | AO29: 0
N30: =IFERROR(__xludf.DUMMYFUNCTION("""COMPUTED_VALUE"""),"") | AB30: =W30+S30 -> 0
B31: EPDMThrmBrks | C31: 4311:03 - EPDM thermal breaks | D31: R-Takeoff LM | J31: Specs | K31: LM | L31: =M26 -> 676.68 | M31: =L31 -> 676.68 | N31: =IFERROR(__xludf.DUMMYFUNCTION("""COMPUTED_VALUE"""),1.0) -> 1 | O31: 1 | P31: 1 | Q31: =M31*N31*O31*P31 -> 676.68 | S31: =R31*Q31 -> 0 | W31: =U31*Q31 -> 0 | AB31: =W31+S31 -> 0 | AM31: 676.68 | AN31: Matched | AO31: 0
N32: =IFERROR(__xludf.DUMMYFUNCTION("""COMPUTED_VALUE"""),"") | AB32: =W32+S32 -> 0
B33: DRBB900Maxam055 | C33: 4311:01 - 0.55bmt BB900 Maxam | D33: R-Sheeting | E33: =IFERROR(__xludf.DUMMYFUNCTION("IF($B$17:$B386="""","""", VLOOKUP( $B$17:$B386, QUERY( IMPORTRANGE(""1Ag27m9YF5mMfJh2E6NipJDFvPLlDI1p-s_1XEnzMHcc"",""Merge!F2:R""), ""select Col1, Col11"", 0 ), 2, FALSE ) ) "),"#REF!") -> #REF! | F33: 9° | H33: 0.55 | J33: Specs | K33: m2 | L33: =L17 -> 602.91 | M33: =L33*E33 -> #REF! | N33: =IFERROR(__xludf.DUMMYFUNCTION("""COMPUTED_VALUE"""),1.0124651257880029) -> 1.0124651 | O33: 1 | P33: 1 | Q33: =M33*N33*O33*P33 -> #REF! | S33: =R33*Q33 -> #REF! | W33: =U33*Q33 -> #REF! | AB33: =W33+S33 -> #REF! | AN33: #REF!
B34: LinerFixSt12x20 | C34: Liner Fixing - STEEL 12X20 PER X100 | D34: R-AdvFixing | J34: Specs | K34: ea | L34: 676.68 | M34: 676.68 | N34: =IFERROR(__xludf.DUMMYFUNCTION("""COMPUTED_VALUE"""),1.0) -> 1 | O34: 1 | P34: 1 | Q34: =M34*N34*O34*P34 -> 676.68 | S34: =R34*Q34 -> 0 | W34: =U34*Q34 -> 0 | AB34: =W34+S34 -> 0 | AM34: 676.68 | AN34: Matched | AO34: 0
N35: =IFERROR(__xludf.DUMMYFUNCTION("""COMPUTED_VALUE"""),"")
A36: 1 | C36: Supply and install 4311: DW Dimond advanced roofing system - 0.55mm BMT AM150 Zincalume Dimond BB900 TBC with Thermakraft 407 Covertek Roof Underlay, Dimond Ashgrid AG40 rail and AB40 post located above all purlins complete with EPDM thermal breaks., Dimond R1.8 75mm thermal BIB insulation over R2.4 95mm BIB insulation, Lap seal tape, and 0.55mm BMT Dimond BB900 TBC Zincalume Base Sheet, as per general notes (A002) | L36: =Q36 -> #REF! | N36: =IFERROR(__xludf.DUMMYFUNCTION("""COMPUTED_VALUE"""),"") | P36: =Q16+Q36 -> #REF! | Q36: =Q37 -> #REF! | S36: =T36/Q36 -> #REF! | T36: =SUM(S37:S55) -> #REF! | V36: =W36/Q36 -> #REF! | W36: =SUM(W37:W55) -> #REF! | X36: =W36/$AC$176/$W$183/$X$173 -> #REF! | Y36: =(T36+W36)=(SUM(AB37:AB55)) -> #REF! | Z36: =(T36+W36)-(SUM(AB37:AB55)) -> #REF! | AD36: =W36+T36 -> #REF! | AE36: =AD36 -> #REF! | AF36: =AE36/$AE$151 -> #REF! | AG36: =AF36*$AG$158 -> #REF! | AH36: =AF36*$AG$161 -> #REF! | AJ36: =ROUND(AK36/L36,2) -> #REF! | AK36: =ROUND(AH36+AG36+AD36,2) -> #REF!
B37: DRBB900Zinc055 | C37: 4311:01 - 0.55mm BMT AM150 Zincalume Dimond BB900 TBC @ 5 deg | D37: R-Sheeting | E37: =IFERROR(__xludf.DUMMYFUNCTION("IF($B$17:$B386="""","""", VLOOKUP( $B$17:$B386, QUERY( IMPORTRANGE(""1Ag27m9YF5mMfJh2E6NipJDFvPLlDI1p-s_1XEnzMHcc"",""Merge!F2:R""), ""select Col1, Col11"", 0 ), 2, FALSE ) ) "),"#REF!") -> #REF! | F37: =IFERROR(__xludf.DUMMYFUNCTION("IFERROR(REGEXEXTRACT(C37,""@\s*(\d+)\s*deg"")&""°"","""") "),"5°") -> 5° | H37: =IFERROR(__xludf.DUMMYFUNCTION("IFERROR(REGEXEXTRACT(C37, ""(\d*\.\d+)mm""), """")"),"0.55") -> 0.55 | J37: Specs | K37: m2 | L37: 1029.42 | M37: =L37*E37 -> #REF! | N37: =IFERROR(__xludf.DUMMYFUNCTION("""COMPUTED_VALUE"""),1.0038198375433474) -> 1.0038198 | O37: 1 | P37: 1 | Q37: =M37*N37*O37*P37 -> #REF! | S37: =R37*Q37 -> #REF! | W37: =U37*Q37 -> #REF! | X37: =W37/$AC$176/$W$183/Y37 -> #REF! | Y37: 10 | Z37: =Q37/X37 -> #REF! | AA37: =27*15/60/8 -> 0.84375 | AB37: =W37+S37 -> #REF! | AN37: #REF!
N38: =IFERROR(__xludf.DUMMYFUNCTION("""COMPUTED_VALUE"""),"") | AB38: =W38+S38 -> 0
B39: DR75mmInsul | C39: Dimond R1.8 75mm thermal BIB insulation | D39: R-Insulation | F39: =F61 -> 5° | J39: Specs | K39: m2 | L39: 921.66 | M39: 921.66 | N39: =IFERROR(__xludf.DUMMYFUNCTION("""COMPUTED_VALUE"""),1.0038198375433474) -> 1.0038198 | O39: 1 | P39: 1 | Q39: =M39*N39*O39*P39 -> 925.18059 | S39: =R39*Q39 -> 0 | W39: =U39*Q39 -> 0 | AB39: =W39+S39 -> 0 | AM39: 921.66 | AN39: Matched | AO39: 0
B40: DR95mmInsul | C40: Dimond R2.4 95mm BIB insulation | D40: R-Insulation | F40: =F39 -> 5° | J40: Specs | K40: m2 | L40: =M39 -> 921.66 | M40: 921.66 | N40: =IFERROR(__xludf.DUMMYFUNCTION("""COMPUTED_VALUE"""),1.0038198375433474) -> 1.0038198 | O40: 1 | P40: 1 | Q40: =M40*N40*O40*P40 -> 925.18059 | S40: =R40*Q40 -> 0 | W40: =U40*Q40 -> 0 | AB40: =W40+S40 -> 0 | AM40: 921.66 | AN40: Matched | AO40: 0
N41: =IFERROR(__xludf.DUMMYFUNCTION("""COMPUTED_VALUE"""),"") | AB41: =W41+S41 -> 0
...

Sheet Template
R1: =IFERROR( IF(B1="", "", VLOOKUP(B1, Data!$B$2:$K$905, 9, FALSE)), "" ) | U1: =IFERROR( IF(B1="", "", VLOOKUP(B1, Data!$B$2:$K$905, 10, FALSE)), "" )
A2: 1
A3: 1
A4: 1
A5: 1
A6: 1
A7: 1
A8: 1 | B8: Project: | C8: =IFERROR(__xludf.DUMMYFUNCTION("IF( Template!D8="""", """", IFERROR( VLOOKUP( Template!D8, IMPORTRANGE( ""1yRKiSiwTOx_Hj9DHPwpMhw9gK8bTY1IeLWGRh62hnCs"", ""Masterlist!E:L"" ), 2, FALSE ) ) ) "),"") | D8: DKR- | K8: DK Roofing BOQ
A9: 1 | B9: Location: | C9: =IFERROR(__xludf.DUMMYFUNCTION("IF( Template!D8="""", """", IFERROR( VLOOKUP( Template!D8, IMPORTRANGE( ""1yRKiSiwTOx_Hj9DHPwpMhw9gK8bTY1IeLWGRh62hnCs"", ""Masterlist!E:L"" ), 3, FALSE ) ) ) "),"")
C10: Building | D10: Timber | I10: 1
A11: 1 | B11: SN | C11: Description | D11: Type | E11: Girth | F11: Degree | G11: Location | H11: BMT | I11: Coating | J11: Specs | K11: Unit | L11: BOQ | M11: TAKEOFF | Q11: Qty | R11: MATERIAL | V11: LABOUR | AD11: TOTAL COST | AE11: For Markup | AF11: factor | AG11: Prelims | AH11: Margin | AJ11: Rate | AK11: Amount
A12: 1 | L12: QTY | M12: Qty | N12: Pitch F | O12: 0 | P12: Unit | R12: Rate | S12: Amount | T12: Total Material Cost | U12: Rate | V12: Amount | W12: Total Labour | AF12: =SUM(AF13) -> 0
A13: 1
A14: 1 | B14: TB | C14: NORTH BOUND ROOFING WORKS | R14: =IFERROR( IF(B14="", "", VLOOKUP(B14, Data!$B$2:$K$905, 9, FALSE)), "" ) | U14: =IFERROR( IF(B14="", "", VLOOKUP(B14, Data!$B$2:$K$905, 10, FALSE)), "" )
A15: 1 | B15: B | C15: Roof Sheeting | R15: =IFERROR( IF(B15="", "", VLOOKUP(B15, Data!$B$2:$K$905, 9, FALSE)), "" ) | U15: =IFERROR( IF(B15="", "", VLOOKUP(B15, Data!$B$2:$K$905, 10, FALSE)), "" )
A16: 1 | C16: Supply and install 0.55mm BMT Dimondek 630 metal roofing, as per plan (A183) | L16: =Q16 -> #REF! | Q16: =Q17+Q22+Q26 -> #REF! | R16: =IFERROR( IF(B16="", "", VLOOKUP(B16, Data!$B$2:$K$905, 9, FALSE)), "" ) | S16: =IFERROR(T16/Q16, 0) -> 0 | T16: =SUM(S17:S29) -> #REF! | U16: =IFERROR( IF(B16="", "", VLOOKUP(B16, Data!$B$2:$K$905, 10, FALSE)), "" ) | V16: =iferror(W16/Q16,"") | W16: =SUM(W17:W29) -> #REF! | X16: =W16/$AC$758/$W$765/$X$755 -> #REF! | Y16: =(T16+W16)=(SUM(AB17:AB29)) -> #REF! | Z16: =(T16+W16)-(SUM(AB17:AB29)) -> #REF! | AD16: =W16+T16 -> #REF! | AE16: =AD16 -> #REF! | AF16: =AE16/$AE$733 -> #REF! | AG16: =AF16*$AG$740 -> #REF! | AH16: =AF16*$AG$743 -> #REF! | AJ16: =ROUND(AK16/L16,2) -> #REF! | AK16: =ROUND(AH16+AG16+AD16,2) -> #REF!
B17: DRDek630Mag055 | C17: 0.55mm BMT Dimondek 630 metal roofing @ 3 deg - at 1200mm purlin spacing | D17: R-Sheeting | E17: =IFERROR(__xludf.DUMMYFUNCTION("IF($B$15:$B1153="""","""", VLOOKUP( $B$15:$B1153, QUERY( IMPORTRANGE(""1Ag27m9YF5mMfJh2E6NipJDFvPLlDI1p-s_1XEnzMHcc"",""Merge!F2:R""), ""select Col1, Col11"", 0 ), 2, FALSE ) ) "),"#REF!") -> #REF! | G17: North Bound | H17: =IFERROR(__xludf.DUMMYFUNCTION("IFERROR(REGEXEXTRACT(C17, ""(\d*\.\d+)mm""), """")"),"0.55") -> 0.55 | I17: Mag | J17: Specs | K17: =IFERROR( IF(B17="", "", VLOOKUP(B17, Data!$B$2:$K$905, 7, FALSE)), "" ) | L17: 24216.66 | M17: =L17*E17 -> #REF! | N17: =IFERROR(__xludf.DUMMYFUNCTION("IF( AND( IFERROR(REGEXEXTRACT(C17,""@\s*(\d+(?:\.\d+)?)\s*deg""),"""")<>"""", F17<>"""" ), ""Pls Confirm °"", IF( IFERROR(REGEXEXTRACT(C17,""@\s*(\d+(?:\.\d+)?)\s*deg""),"""")<>"""", 1/COS(RADIANS(REGEXEXTRACT(C17,""@\s*(\d+(?:\.\d"&"+)?)\s*deg""))), IF( F17<>"""", IF( ISNUMBER(SEARCH(""|"",F17)), 1/COS( ATAN( TAN(RADIANS(VALUE(INDEX(SPLIT(F17,""|""),1)))) * TAN(RADIANS(VALUE(INDEX(SPLIT(F17,""|""),2)))) / "&" SQRT( TAN(RADIANS(VALUE(INDEX(SPLIT(F17,""|""),1))))^2 + TAN(RADIANS(VALUE(INDEX(SPLIT(F17,""|""),2))))^2 ) ) ), 1/COS(RADIANS(VALUE(F17))) ), 1 ) ) )"),1.001372345997921) -> 1.0013723 | O17: 1 | P17: 1 | Q17: =M17*N17*O17*P17 -> #REF! | R17: =IFERROR( IF(B17="", "", VLOOKUP(B17, Data!$B$2:$K$905, 9, FALSE)), "" ) | S17: =R17*Q17 -> #REF! | U17: =IFERROR( IF(B17="", "", VLOOKUP(B17, Data!$B$2:$K$905, 10, FALSE)), "" ) | W17: =U17*Q17 -> #REF! | AB17: =W17+S17 -> #REF!
B18: DRDek630Clip | C18: Dimondek 630 Clip | D18: R-Clips | E18: 1.2 | H18: =IFERROR(__xludf.DUMMYFUNCTION("IFERROR(REGEXEXTRACT(C18, ""(\d*\.\d+)mm""), """")"),"") | J18: No Specs | K18: =IFERROR( IF(B18="", "", VLOOKUP(B18, Data!$B$2:$K$905, 7, FALSE)), "" ) | M18: =roundup(L17/E18,0)+1 -> 20182 | N18: =N17 -> 1.0013723 | O18: 1 | P18: 1 | Q18: =M18*N18*O18*P18 -> 20209.697 | R18: =IFERROR( IF(B18="", "", VLOOKUP(B18, Data!$B$2:$K$905, 9, FALSE)), "" ) | S18: =R18*Q18 -> 0 | U18: =IFERROR( IF(B18="", "", VLOOKUP(B18, Data!$B$2:$K$905, 10, FALSE)), "" ) | W18: =U18*Q18 -> 0 | AB18: =W18+S18 -> 0
B19: DRDek630T17 | C19: Wafer 10x65 T17 SD No Neo | D19: R-Fixings | J19: No Specs | K19: =IFERROR( IF(B19="", "", VLOOKUP(B19, Data!$B$2:$K$905, 7, FALSE)), "" ) | M19: =M18*2 -> 40364 | N19: =N18 -> 1.0013723 | O19: 1 | P19: 1 | Q19: =M19*N19*O19*P19 -> 40419.393 | R19: =IFERROR( IF(B19="", "", VLOOKUP(B19, Data!$B$2:$K$905, 9, FALSE)), "" ) | S19: =R19*Q19 -> 0 | U19: =IFERROR( IF(B19="", "", VLOOKUP(B19, Data!$B$2:$K$905, 10, FALSE)), "" ) | W19: =U19*Q19 -> 0 | AB19: =W19+S19 -> 0
A20: Ma | B20: 630WindClamp | C20: Windclamp | D20: R-Windclamp | J20: No Specs | K20: =IFERROR( IF(B20="", "", VLOOKUP(B20, Data!$B$2:$K$905, 7, FALSE)), "" ) | M20: =235+235 -> 470 | N20: =N19 -> 1.0013723 | O20: 1 | P20: 1 | Q20: =M20*N20*O20*P20 -> 470.645 | R20: =IFERROR( IF(B20="", "", VLOOKUP(B20, Data!$B$2:$K$905, 9, FALSE)), "" ) | S20: =R20*Q20 -> 0 | U20: =IFERROR( IF(B20="", "", VLOOKUP(B20, Data!$B$2:$K$905, 10, FALSE)), "" ) | W20: =U20*Q20 -> 0
B22: DRDek630Mag055 | C22: 0.55mm BMT Dimondek 630 metal roofing @ 3 deg - at 900mm purlin spacing | D22: R-Sheeting | E22: =IFERROR(__xludf.DUMMYFUNCTION("IF($B$15:$B1152="""","""", VLOOKUP( $B$15:$B1152, QUERY( IMPORTRANGE(""1Ag27m9YF5mMfJh2E6NipJDFvPLlDI1p-s_1XEnzMHcc"",""Merge!F2:R""), ""select Col1, Col11"", 0 ), 2, FALSE ) ) "),"#REF!") -> #REF! | G22: North Bound | H22: =IFERROR(__xludf.DUMMYFUNCTION("IFERROR(REGEXEXTRACT(C22, ""(\d*\.\d+)mm""), """")"),"0.55") -> 0.55 | I22: Mag | J22: Specs | K22: =IFERROR( IF(B22="", "", VLOOKUP(B22, Data!$B$2:$K$905, 7, FALSE)), "" ) | L22: =2101.32+ 1258.92 -> 3360.24 | M22: =L22*E22 -> #REF! | N22: =IFERROR(__xludf.DUMMYFUNCTION("IF( AND( IFERROR(REGEXEXTRACT(C22,""@\s*(\d+(?:\.\d+)?)\s*deg""),"""")<>"""", F22<>"""" ), ""Pls Confirm °"", IF( IFERROR(REGEXEXTRACT(C22,""@\s*(\d+(?:\.\d+)?)\s*deg""),"""")<>"""", 1/COS(RADIANS(REGEXEXTRACT(C22,""@\s*(\d+(?:\.\d"&"+)?)\s*deg""))), IF( F22<>"""", IF( ISNUMBER(SEARCH(""|"",F22)), 1/COS( ATAN( TAN(RADIANS(VALUE(INDEX(SPLIT(F22,""|""),1)))) * TAN(RADIANS(VALUE(INDEX(SPLIT(F22,""|""),2)))) / "&" SQRT( TAN(RADIANS(VALUE(INDEX(SPLIT(F22,""|""),1))))^2 + TAN(RADIANS(VALUE(INDEX(SPLIT(F22,""|""),2))))^2 ) ) ), 1/COS(RADIANS(VALUE(F22))) ), 1 ) ) )"),1.001372345997921) -> 1.0013723 | O22: 1 | P22: 1 | Q22: =M22*N22*O22*P22 -> #REF! | R22: =IFERROR( IF(B22="", "", VLOOKUP(B22, Data!$B$2:$K$905, 9, FALSE)), "" ) | S22: =R22*Q22 -> #REF! | U22: =IFERROR( IF(B22="", "", VLOOKUP(B22, Data!$B$2:$K$905, 10, FALSE)), "" ) | W22: =U22*Q22 -> #REF! | AB22: =W22+S22 -> #REF!
B23: DRDek630Clip | C23: Dimondek 630 Clip | D23: R-Clips | E23: 0.9 | H23: =IFERROR(__xludf.DUMMYFUNCTION("IFERROR(REGEXEXTRACT(C23, ""(\d*\.\d+)mm""), """")"),"") | J23: No Specs | K23: =IFERROR( IF(B23="", "", VLOOKUP(B23, Data!$B$2:$K$905, 7, FALSE)), "" ) | M23: =roundup(L22/E23,0)+1 -> 3735 | N23: =N22 -> 1.0013723 | O23: 1 | P23: 1 | Q23: =M23*N23*O23*P23 -> 3740.1257 | R23: =IFERROR( IF(B23="", "", VLOOKUP(B23, Data!$B$2:$K$905, 9, FALSE)), "" ) | S23: =R23*Q23 -> 0 | U23: =IFERROR( IF(B23="", "", VLOOKUP(B23, Data!$B$2:$K$905, 10, FALSE)), "" ) | W23: =U23*Q23 -> 0 | AB23: =W23+S23 -> 0
B24: DRDek630T17 | C24: Wafer 10x65 T17 SD No Neo | D24: R-Fixings | J24: No Specs | K24: =IFERROR( IF(B24="", "", VLOOKUP(B24, Data!$B$2:$K$905, 7, FALSE)), "" ) | M24: =M23*2 -> 7470 | N24: =N23 -> 1.0013723 | O24: 1 | P24: 1 | Q24: =M24*N24*O24*P24 -> 7480.2514 | R24: =IFERROR( IF(B24="", "", VLOOKUP(B24, Data!$B$2:$K$905, 9, FALSE)), "" ) | S24: =R24*Q24 -> 0 | U24: =IFERROR( IF(B24="", "", VLOOKUP(B24, Data!$B$2:$K$905, 10, FALSE)), "" ) | W24: =U24*Q24 -> 0 | AB24: =W24+S24 -> 0
B26: DRDek630Mag055 | C26: 0.55mm BMT Dimondek 630 metal roofing @ 3 deg - at 700mm purlin spacing | D26: R-Sheeting | E26: =IFERROR(__xludf.DUMMYFUNCTION("IF($B$15:$B1152="""","""", VLOOKUP( $B$15:$B1152, QUERY( IMPORTRANGE(""1Ag27m9YF5mMfJh2E6NipJDFvPLlDI1p-s_1XEnzMHcc"",""Merge!F2:R""), ""select Col1, Col11"", 0 ), 2, FALSE ) ) "),"#REF!") -> #REF! | G26: North Bound | H26: =IFERROR(__xludf.DUMMYFUNCTION("IFERROR(REGEXEXTRACT(C26, ""(\d*\.\d+)mm""), """")"),"0.55") -> 0.55 | I26: Mag | J26: Specs | K26: =IFERROR( IF(B26="", "", VLOOKUP(B26, Data!$B$2:$K$905, 7, FALSE)), "" ) | L26: =1666.08+ 1696.5 -> 3362.58 | M26: =L26*E26 -> #REF! | N26: =IFERROR(__xludf.DUMMYFUNCTION("IF( AND( IFERROR(REGEXEXTRACT(C26,""@\s*(\d+(?:\.\d+)?)\s*deg""),"""")<>"""", F26<>"""" ), ""Pls Confirm °"", IF( IFERROR(REGEXEXTRACT(C26,""@\s*(\d+(?:\.\d+)?)\s*deg""),"""")<>"""", 1/COS(RADIANS(REGEXEXTRACT(C26,""@\s*(\d+(?:\.\d"&"+)?)\s*deg""))), IF( F26<>"""", IF( ISNUMBER(SEARCH(""|"",F26)), 1/COS( ATAN( TAN(RADIANS(VALUE(INDEX(SPLIT(F26,""|""),1)))) * TAN(RADIANS(VALUE(INDEX(SPLIT(F26,""|""),2)))) / "&" SQRT( TAN(RADIANS(VALUE(INDEX(SPLIT(F26,""|""),1))))^2 + TAN(RADIANS(VALUE(INDEX(SPLIT(F26,""|""),2))))^2 ) ) ), 1/COS(RADIANS(VALUE(F26))) ), 1 ) ) )"),1.001372345997921) -> 1.0013723 | O26: 1 | P26: 1 | Q26: =M26*N26*O26*P26 -> #REF! | R26: =IFERROR( IF(B26="", "", VLOOKUP(B26, Data!$B$2:$K$905, 9, FALSE)), "" ) | S26: =R26*Q26 -> #REF! | U26: =IFERROR( IF(B26="", "", VLOOKUP(B26, Data!$B$2:$K$905, 10, FALSE)), "" ) | W26: =U26*Q26 -> #REF! | AB26: =W26+S26 -> #REF!
B27: DRDek630Clip | C27: Dimondek 630 Clip | D27: R-Clips | E27: 0.7 | H27: =IFERROR(__xludf.DUMMYFUNCTION("IFERROR(REGEXEXTRACT(C27, ""(\d*\.\d+)mm""), """")"),"") | J27: No Specs | K27: =IFERROR( IF(B27="", "", VLOOKUP(B27, Data!$B$2:$K$905, 7, FALSE)), "" ) | M27: =roundup(L26/E27,0)+1 -> 4805 | N27: =N26 -> 1.0013723 | O27: 1 | P27: 1 | Q27: =M27*N27*O27*P27 -> 4811.5941 | R27: =IFERROR( IF(B27="", "", VLOOKUP(B27, Data!$B$2:$K$905, 9, FALSE)), "" ) | S27: =R27*Q27 -> 0 | U27: =IFERROR( IF(B27="", "", VLOOKUP(B27, Data!$B$2:$K$905, 10, FALSE)), "" ) | W27: =U27*Q27 -> 0 | AB27: =W27+S27 -> 0
B28: DRDek630T17 | C28: Wafer 10x65 T17 SD No Neo | D28: R-Fixings | J28: No Specs | K28: =IFERROR( IF(B28="", "", VLOOKUP(B28, Data!$B$2:$K$905, 7, FALSE)), "" ) | M28: =M27*2 -> 9610 | N28: =N27 -> 1.0013723 | O28: 1 | P28: 1 | Q28: =M28*N28*O28*P28 -> 9623.1882 | R28: =IFERROR( IF(B28="", "", VLOOKUP(B28, Data!$B$2:$K$905, 9, FALSE)), "" ) | S28: =R28*Q28 -> 0 | U28: =IFERROR( IF(B28="", "", VLOOKUP(B28, Data!$B$2:$K$905, 10, FALSE)), "" ) | W28: =U28*Q28 -> 0 | AB28: =W28+S28 -> 0
R29: =IFERROR( IF(B29="", "", VLOOKUP(B29, Data!$B$2:$K$905, 9, FALSE)), "" ) | U29: =IFERROR( IF(B29="", "", VLOOKUP(B29, Data!$B$2:$K$905, 10, FALSE)), "" ) | AB29: =W29+S29 -> 0
A30: 1 | B30: B | C30: Underlay | R30: =IFERROR( IF(B30="", "", VLOOKUP(B30, Data!$B$2:$K$905, 9, FALSE)), "" ) | U30: =IFERROR( IF(B30="", "", VLOOKUP(B30, Data!$B$2:$K$905, 10, FALSE)), "" )
A31: 1 | C31: Supply and install underlay | L31: =Q31 -> #REF! | Q31: =Q32 -> #REF! | R31: =IFERROR( IF(B31="", "", VLOOKUP(B31, Data!$B$2:$K$905, 9, FALSE)), "" ) | S31: =IFERROR(T31/Q31, 0) -> 0 | T31: =SUM(S32:S34) -> #REF! | U31: =IFERROR( IF(B31="", "", VLOOKUP(B31, Data!$B$2:$K$905, 10, FALSE)), "" ) | V31: =iferror(W31/Q31,"") | W31: =SUM(W32:W34) -> #REF! | X31: =W31/$AC$758/$W$765/$X$755 -> #REF! | Y31: =(T31+W31)=(SUM(AB32:AB34)) -> #REF! | Z31: =(T31+W31)-(SUM(AB32:AB34)) -> #REF! | AD31: =W31+T31 -> #REF! | AE31: =AD31 -> #REF! | AF31: =AE31/$AE$733 -> #REF! | AG31: =AF31*$AG$740 -> #REF! | AH31: =AF31*$AG$743 -> #REF! | AJ31: =ROUND(AK31/L31,2) -> #REF! | AK31: =ROUND(AH31+AG31+AD31,2) -> #REF!
A32: Ma | B32: TKUF405 | C32: Thermakraft Covertek 405 self supporting fire retardant | D32: R-Underlay | E32: =IFERROR(__xludf.DUMMYFUNCTION("IF($B$15:$B927="""","""", VLOOKUP( $B$15:$B927, QUERY( IMPORTRANGE(""1Ag27m9YF5mMfJh2E6NipJDFvPLlDI1p-s_1XEnzMHcc"",""Merge!F2:R""), ""select Col1, Col11"", 0 ), 2, FALSE ) ) "),"#REF!") -> #REF! | G32: North Bound | H32: =IFERROR(__xludf.DUMMYFUNCTION("IFERROR(REGEXEXTRACT(C32, ""(\d*\.\d+)mm""), """")"),"") | J32: Specs | K32: =IFERROR( IF(B32="", "", VLOOKUP(B32, Data!$B$2:$K$905, 7, FALSE)), "" ) | L32: =Q16 -> #REF! | M32: =((L32)/(E32-0.15))*0.15+(L32) -> #REF! | N32: =IFERROR(__xludf.DUMMYFUNCTION("IF(B32="""", """", IFERROR(1 / COS(RADIANS(REGEXEXTRACT(F32,""(\d+)""))), 1))"),1.0) -> 1 | O32: 1 | P32: 1 | Q32: =M32*N32*O32*P32 -> #REF! | R32: =IFERROR( IF(B32="", "", VLOOKUP(B32, Data!$B$2:$K$905, 9, FALSE)), "" ) | S32: =R32*Q32 -> #REF! | U32: =IFERROR( IF(B32="", "", VLOOKUP(B32, Data!$B$2:$K$905, 10, FALSE)), "" ) | W32: =U32*Q32 -> #REF! | AB32: =W32+S32 -> #REF!
A33: Ma | B33: TKGenTape | C33: Thermakraft White General Purpose Tape (60 mm × 66 m) | D33: R-UTape | E33: =E32 -> #REF! | H33: =IFERROR(__xludf.DUMMYFUNCTION("IF($B$15:$B927="""","""", VLOOKUP( $B$15:$B927, QUERY( IMPORTRANGE(""1Ag27m9YF5mMfJh2E6NipJDFvPLlDI1p-s_1XEnzMHcc"",""Merge!F2:R""), ""select Col1, Col11"", 0 ), 2, FALSE ) ) "),"#REF!") -> #REF! | J33: No Specs | K33: =IFERROR( IF(B33="", "", VLOOKUP(B33, Data!$B$2:$K$905, 7, FALSE)), "" ) | M33: =M32/E33/H33 -> #REF! | N33: =N32 -> 1 | O33: 1 | P33: 1 | Q33: =M33*N33*O33*P33 -> #REF! | R33: =IFERROR( IF(B33="", "", VLOOKUP(B33, Data!$B$2:$K$905, 9, FALSE)), "" ) | S33: =R33*Q33 -> #REF! | U33: =IFERROR( IF(B33="", "", VLOOKUP(B33, Data!$B$2:$K$905, 10, FALSE)), "" ) | W33: =U33*Q33 -> #REF! | AB33: =W33+S33 -> #REF!
K34: =IFERROR( IF(B34="", "", VLOOKUP(B34, Data!$B$2:$K$905, 7, FALSE)), "" ) | N34: =IFERROR(__xludf.DUMMYFUNCTION("IF(B34="""", """", IFERROR(1 / COS(RADIANS(REGEXEXTRACT(F34,""(\d+)""))), 1))"),"") | R34: =IFERROR( IF(B34="", "", VLOOKUP(B34, Data!$B$2:$K$905, 9, FALSE)), "" ) | U34: =IFERROR( IF(B34="", "", VLOOKUP(B34, Data!$B$2:$K$905, 10, FALSE)), "" )
A35: 1 | C35: Safety mesh | R35: =IFERROR( IF(B35="", "", VLOOKUP(B35, Data!$B$2:$K$905, 9, FALSE)), "" ) | U35: =IFERROR( IF(B35="", "", VLOOKUP(B35, Data!$B$2:$K$905, 10, FALSE)), "" )
A36: 1 | C36: Supply and install safety mesh | L36: =Q36 -> #REF! | Q36: =Q37 -> #REF! | R36: =IFERROR( IF(B36="", "", VLOOKUP(B36, Data!$B$2:$K$905, 9, FALSE)), "" ) | S36: =iferror(T36/Q36,"") | T36: =SUM(S37:S38) -> #REF! | U36: =IFERROR( IF(B36="", "", VLOOKUP(B36, Data!$B$2:$K$905, 10, FALSE)), "" ) | V36: =iferror(W36/Q36,"") | W36: =SUM(W37:W38) -> #REF! | X36: =W36/$AC$758/$W$765/$X$755 -> #REF! | Y36: =(T36+W36)=(SUM(AB37:AB38)) -> #REF! | Z36: =(T36+W36)-(SUM(AB37:AB38)) -> #REF! | AD36: =W36+T36 -> #REF! | AE36: =AD36 -> #REF! | AF36: =AE36/$AE$733 -> #REF! | AG36: =AF36*$AG$740 -> #REF! | AH36: =AF36*$AG$743 -> #REF! | AJ36: =ROUND(AK36/L36,2) -> #REF! | AK36: =ROUND(AH36+AG36+AD36,2) -> #REF!
A37: Ma | B37: Safetymesh | C37: Safety mesh | D37: R-Safety Mesh | G37: North Bound | H37: =IFERROR(__xludf.DUMMYFUNCTION("IFERROR(REGEXEXTRACT(C37, ""(\d*\.\d+)mm""), """")"),"") | J37: No Specs | K37: m2 | M37: =M32 -> #REF! | N37: =IFERROR(__xludf.DUMMYFUNCTION("IF(B37="""", """", IFERROR(1 / COS(RADIANS(REGEXEXTRACT(F37,""(\d+)""))), 1))"),1.0) -> 1 | O37: 1 | P37: 1 | Q37: =M37*N37*O37*P37 -> #REF! | R37: =IFERROR( IF(B37="", "", VLOOKUP(B37, Data!$B$2:$K$905, 9, FALSE)), "" ) | S37: =R37*Q37 -> #REF! | U37: =IFERROR( IF(B37="", "", VLOOKUP(B37, Data!$B$2:$K$905, 10, FALSE)), "" ) | W37: =U37*Q37 -> #REF! | AB37: =W37+S37 -> #REF!
N38: =IFERROR(__xludf.DUMMYFUNCTION("IF(B38="""", """", IFERROR(1 / COS(RADIANS(REGEXEXTRACT(F38,""(\d+)""))), 1))"),"") | R38: =IFERROR( IF(B38="", "", VLOOKUP(B38, Data!$B$2:$K$905, 9, FALSE)), "" ) | U38: =IFERROR( IF(B38="", "", VLOOKUP(B38, Data!$B$2:$K$905, 10, FALSE)), "" ) | AB38: =W38+S38 -> 0
A39: 1 | B39: B | C39: Flashing/Capping | R39: =IFERROR( IF(B39="", "", VLOOKUP(B39, Data!$B$2:$K$905, 9, FALSE)), "" ) | U39: =IFERROR( IF(B39="", "", VLOOKUP(B39, Data!$B$2:$K$905, 10, FALSE)), "" )
A40: 1 | C40: Supply and install 0.55mm BMT ridge cap flashing (530/3B), as per detail A (A-3000) | L40: =Q40 -> 0 | Q40: =Q41 -> 0 | R40: =IFERROR( IF(B40="", "", VLOOKUP(B40, Data!$B$2:$K$905, 9, FALSE)), "" ) | S40: =IFERROR(T40/Q40, 0) -> 0 | T40: =SUM(S41:S48) -> 0 | U40: =IFERROR( IF(B40="", "", VLOOKUP(B40, Data!$B$2:$K$905, 10, FALSE)), "" ) | V40: =W40/Q40 -> #DIV/0! | W40: =SUM(W41:W48) -> 0 | X40: =W40/$AC$135/$W$142/$X$132 -> #DIV/0! | Y40: =(T40+W40)=(SUM(AB41:AB48)) -> TRUE | Z40: =(T40+W40)-(SUM(AB41:AB48)) -> 0 | AD40: =W40+T40 -> 0 | AE40: =AD40 -> 0 | AF40: =AE40/$AE$110 -> #DIV/0! | AG40: =AF40*$AG$117 -> #DIV/0! | AH40: =AF40*$AG$120 -> #DIV/0! | AJ40: =ROUND(AK40/L40,2) -> #DIV/0! | AK40: =ROUND(AH40+AG40+AD40,2) -> #DIV/0!
A41: Fl | B41: =IFERROR(__xludf.DUMMYFUNCTION("IFERROR( IF(C41="""","""", IF(OR(REGEXMATCH(D41,""(?i)-Flashing""), REGEXMATCH(D41,""(?i)-EavesGut""), REGEXMATCH(D41,""(?i)Valley"")), ""DR"" & TEXT( ROUNDUP( VALUE(MID(C41, FIND(""("",C41)+1, FIND(""/"","&"C41)-FIND(""("",C41)-1)) / 50, 0) * 50, ""0"" ) & MID(C41, FIND(""/"",C41)+1, FIND("")"",C41)-FIND(""/"",C41)-1) & TEXT(H41*100,""0"") & I41, IF(AND(D41=""Roof Sheet"", REGEXMATCH(C41,""(?i)KS\d{4}[A-Z]{2}"""&")), REGEXEXTRACT(C41,""(?i)KS\d{4}[A-Z]{2}""), IF(AND(REGEXMATCH(D41,""(?i)-DP""), REGEXMATCH(C41,""(?i)Downpipe"")), ""dp"" & REGEXEXTRACT(C41,""(\d+)"") & ""mm"", IF(AND(REGEXMATCH(D41,""(?i)Bracket""), REGEXMATCH(C41,""(?i)Bracket"&""")), ""Brkt"" & REGEXEXTRACT(C41,""(\d+)"") & ""mm"", IF(AND(REGEXMATCH(D41,""(?i)-OP""), REGEXMATCH(C41,""(?i)pops"")), ""op"" & REGEXEXTRACT(C41,""(\d+)"") & ""mm"", IF(OR(D41=""R-FFTop"", D41=""R-FFBottom"", D41=""R-FFSide""), "&" IF(REGEXMATCH(C41,""(?i)Profiled.*Top|Top.*Profiled""),""pfft"", IF(REGEXMATCH(C41,""(?i)Profiled.*Bottom|Bottom.*Profiled""),""pffb"", IF(REGEXMATCH(C41,""(?i)Square""),""sff"",""""))), IF(REGEXMATCH(D41,""(?i)-Rivets""),""Rvt"""&", IF(REGEXMATCH(D41,""(?i)Silicone""),""300ml"", IF(REGEXMATCH(D41,""(?i)R-Butyl""),""300ml"", IF(REGEXMATCH(D41,""(?i)Fix""),""GenFix"", IF(AND(REGEXMATCH(C41,""(?i)Timber""), REGEXMATCH(D41,""(?i)Timber"")),""tp"", IF(AND(REGEXMATCH("&"C41,""(?i)Vent G1275""), REGEXMATCH(D41,""(?i)Comb FIller"")),""CFV1275"", IF(REGEXMATCH(C41,""(?i)DPC""),""dpc"", IF(REGEXMATCH(C41,""(?i)Concealed Clips""),""ConClips"", IF(REGEXMATCH(D41,""(?i)-Takeoff ea""),""Takeoff ea"", IF(REGEXMATC"&"H(D41,""(?i)-Takeoff LM""),""Takeoff LM"", IF(REGEXMATCH(D41,""(?i)-Takeoff m2""),""Takeoff m2"", IF(D41=""R-TU/TD"",""TU/TD"",""""))))))))))))))))) )))"),"DR5503B55Mag") -> DR5503B55Mag | C41: 0.55mm BMT ridge cap flashing (530/3B) | D41: R-Flashing | E41: =VALUE(MID(C41, FIND("(", C41)+1, FIND("/", C41)-FIND("(", C41)-1)) / 1000 -> 0.53 | H41: =IFERROR(__xludf.DUMMYFUNCTION("IFERROR(REGEXEXTRACT(C41, ""(\d*\.\d+)mm""), """")"),"0.55") -> 0.55 | I41: Mag | J41: Specs | K41: =IFERROR( IF(B41="", "", VLOOKUP(B41, Data!$B$2:$K$905, 7, FALSE)), "" ) | N41: =IFERROR(__xludf.DUMMYFUNCTION("IF( AND( IFERROR(REGEXEXTRACT(C41,""@\s*(\d+(?:\.\d+)?)\s*deg""),"""")<>"""", F41<>"""" ), ""Pls Confirm °"", IF( IFERROR(REGEXEXTRACT(C41,""@\s*(\d+(?:\.\d+)?)\s*deg""),"""")<>"""", 1/COS(RADIANS(REGEXEXTRACT(C41,""@\s*(\d+(?:\.\d"&"+)?)\s*deg""))), IF( F41<>"""", IF( ISNUMBER(SEARCH(""|"",F41)), 1/COS( ATAN( TAN(RADIANS(VALUE(INDEX(SPLIT(F41,""|""),1)))) * TAN(RADIANS(VALUE(INDEX(SPLIT(F41,""|""),2)))) / "&" SQRT( TAN(RADIANS(VALUE(INDEX(SPLIT(F41,""|""),1))))^2 + TAN(RADIANS(VALUE(INDEX(SPLIT(F41,""|""),2))))^2 ) ) ), 1/COS(RADIANS(VALUE(F41))) ), 1 ) ) )"),1.0) -> 1 | O41: 1 | P41: 1 | Q41: =M41*N41*O41*P41 -> 0 | R41: =IFERROR( IF(B41="", "", VLOOKUP(B41, Data!$B$2:$K$905, 9, FALSE)), "" ) | S41: =R41*Q41 -> 0 | U41: =IFERROR( IF(B41="", "", VLOOKUP(B41, Data!$B$2:$K$905, 10, FALSE)), "" ) | W41: =U41*Q41 -> 0 | AB41: =W41+S41 -> 0
B42: =IFERROR(__xludf.DUMMYFUNCTION("IFERROR( IF(C42="""","""", IF(OR(REGEXMATCH(D42,""(?i)-Flashing""), REGEXMATCH(D42,""(?i)-EavesGut""), REGEXMATCH(D42,""(?i)Valley"")), ""DR"" & TEXT( ROUNDUP( MIN( VALUE(MID(C42, FIND("&"""("",C42)+1, FIND(""/"",C42)-FIND(""("",C42)-1)), 1200 ) / 50, 0 ) * 50, ""0"" ) & MID(C42, FIND(""/"",C42)+1, FIND("")"",C42)-FIND(""/"",C42)-1) & TEXT(H42*100,""0"") & I42,"&" IF(AND(D42=""Roof Sheet"", REGEXMATCH(C42,""(?i)KS\d{4}[A-Z]{2}"")), REGEXEXTRACT(C42,""(?i)KS\d{4}[A-Z]{2}""), IF(AND(REGEXMATCH(D42,""(?i)-DP""), REGEXMATCH(C42,""(?i)Downpipe"")), ""dp"" & REGEXEXTRACT(C42,""(\d+)"") & ""mm"", "&" IF(AND(REGEXMATCH(D42,""(?i)Bracket""), REGEXMATCH(C42,""(?i)Bracket"")), ""Brkt"" & REGEXEXTRACT(C42,""(\d+)"") & ""mm"", IF(AND(REGEXMATCH(D42,""(?i)-OP""), REGEXMATCH(C42,""(?i)pops"")), ""op"" & REGEXEXTRACT(C42,""(\d+)"") & ""mm"""&", IF(OR(D42=""R-FFTop"", D42=""R-FFBottom"", D42=""R-FFSide""), IF(REGEXMATCH(C42,""(?i)Profiled.*Top|Top.*Profiled""),""pfft"", IF(REGEXMATCH(C42,""(?i)Profiled.*Bottom|Bottom.*Profiled""),""pffb"", IF(REGEXMATCH(C42,""(?i)Squ"&"are""),""sff"",""""))), IF(REGEXMATCH(D42,""(?i)-Rivets""),""Rvt"", IF(REGEXMATCH(D42,""(?i)Silicone""),""300ml"", IF(REGEXMATCH(D42,""(?i)R-Butyl""),""300ml"", IF(REGEXMATCH(D42,""(?i)Fix""),""GenFix"", IF(AND(REGEXMATCH(C42,""(?i)Tim"&"ber""), REGEXMATCH(D42,""(?i)Timber"")),""tp"", IF(AND(REGEXMATCH(C42,""(?i)Vent G1275""), REGEXMATCH(D42,""(?i)Comb FIller"")),""CFV1275"", IF(REGEXMATCH(C42,""(?i)DPC""),""dpc"", IF(REGEXMATCH(C42,""(?i)Concealed Clips""),""ConClips"", I"&"F(REGEXMATCH(D42,""(?i)-Takeoff ea""),""Takeoff ea"", IF(REGEXMATCH(D42,""(?i)-Takeoff LM""),""Takeoff LM"", IF(REGEXMATCH(D42,""(?i)-Takeoff m2""),""Takeoff m2"", IF(D42=""R-TU/TD"",""TU/TD"",""""))))))))))))))))) )))"),"300ml") -> 300ml | C42: Silicone 300ml | D42: R-Silicone | E42: =E41 -> 0.53 | F42: =IFERROR(__xludf.DUMMYFUNCTION("iferror(ROUND( DEGREES( ATAN( TAN(RADIANS(VALUE(INDEX(SPLIT(F41,""|""),1)))) * TAN(RADIANS(VALUE(INDEX(SPLIT(F41,""|""),2)))) / SQRT( TAN(RADIANS(VALUE(INDEX(SPLIT(F41,""|""),1))))^2 + TAN(RADIANS(VALUE(INDEX("&"SPLIT(F41,""|""),2))))^2 ) ) ), 2 ))"),"") | H42: =IFERROR(__xludf.DUMMYFUNCTION("IFERROR(REGEXEXTRACT(C42, ""(\d*\.\d+)mm""), """")"),"") | J42: No Specs | K42: =IFERROR( IF(B42="", "", VLOOKUP(B42, Data!$B$2:$K$905, 7, FALSE)), "" ) | M42: =(ROUNDDOWN((M41/5.7)+2,0)*E42)/8 -> 0.1325 | N42: =if(B42="","",(if(N41="",N40,N41))) -> 1 | O42: 1 | P42: 1 | Q42: =M42*N42*O42*P42 -> 0.1325 | R42: =IFERROR( IF(B42="", "", VLOOKUP(B42, Data!$B$2:$K$905, 9, FALSE)), "" ) | S42: =R42*Q42 -> 0 | U42: =IFERROR( IF(B42="", "", VLOOKUP(B42, Data!$B$2:$K$905, 10, FALSE)), "" ) | W42: =U42*Q42 -> 0 | AB42: =W42+S42 -> 0
...

Sheet Pricing
R1: =IFERROR( IF(B1="", "", VLOOKUP(B1, Data!$B$2:$K$905, 9, FALSE)), "" ) | U1: =IFERROR( IF(B1="", "", VLOOKUP(B1, Data!$B$2:$K$905, 10, FALSE)), "" )
A2: 1
A3: 1
A4: 1
A5: 1
A6: 1
A7: 1
A8: 1 | B8: Project: | C8: =IFERROR(__xludf.DUMMYFUNCTION("IF( Pricing!D8="""", """", IFERROR( VLOOKUP( Pricing!D8, IMPORTRANGE( ""1yRKiSiwTOx_Hj9DHPwpMhw9gK8bTY1IeLWGRh62hnCs"", ""Masterlist!E:L"" ), 2, FALSE ) ) ) "),"Lakecrest Townhouses") -> Lakecrest Townhouses | D8: DKR-92 | K8: DK Roofing BOQ
A9: 1 | B9: Location: | C9: =IFERROR(__xludf.DUMMYFUNCTION("IF( Pricing!D8="""", """", IFERROR( VLOOKUP( Pricing!D8, IMPORTRANGE( ""1yRKiSiwTOx_Hj9DHPwpMhw9gK8bTY1IeLWGRh62hnCs"", ""Masterlist!E:L"" ), 3, FALSE ) ) ) "),"Tauhara Ridge Drive, Richmond Heights, Taupō 3330, New Zealand") -> Tauhara Ridge Drive, Richmond Heights, Taupō 3330, New Zealand
C10: Building | D10: Timber | I10: 1
A11: 1 | B11: SN | C11: Description | D11: Type | E11: Girth | F11: Degree | G11: Location | H11: BMT | I11: Coating | J11: Specs | K11: Unit | L11: BOQ | M11: TAKEOFF | Q11: Qty | R11: MATERIAL | V11: LABOUR | AD11: TOTAL COST | AE11: For Markup | AF11: factor | AG11: Prelims | AH11: Margin | AJ11: Rate | AK11: Amount
A12: 1 | L12: QTY | M12: Qty | N12: Pitch F | O12: 0 | P12: Unit | R12: Rate | S12: Amount | T12: Total Material Cost | U12: Rate | V12: Amount | W12: Total Labour | AF12: =SUM(AF13) -> 0
A13: 1
A14: 1 | B14: TB | C14: ROOFING WORKS | R14: {=IFERROR( IF( OR(D14="R-Flashing",D14="W-Flashing",D14="R-BG"), LET( StartRow, MATCH( I14&"♦"&H14, Material!$I:$I&"♦"&Material!$J:$J, 0 ), INDEX( Material!$J:$AF, StartRow+1+MATCH( CEILING(E14*1000,50), INDEX(Material!$I:$I,StartRow+2):INDEX(Material!$I:$I,StartRow+25), 0 ), MATCH( G14, INDEX(Material!$I:$V,StartRow+1,0), 0 ) ) ), XLOOKUP(C14,Material!$A:$A,Material!$D:$D) ), "")} | U14: {=IFERROR( IF( D14="R-Flashing", XLOOKUP(CEILING(E14*1000,50),Material!I:I,Material!X:X), XLOOKUP(C14,Material!A:A,Material!E:E) ), "" )}
A15: 1 | B15: B | C15: Roof Sheeting | R15: {=IFERROR( IF( OR(D15="R-Flashing",D15="W-Flashing",D15="R-BG"), LET( StartRow, MATCH( I15&"♦"&H15, Material!$I:$I&"♦"&Material!$J:$J, 0 ), INDEX( Material!$J:$AF, StartRow+1+MATCH( CEILING(E15*1000,50), INDEX(Material!$I:$I,StartRow+2):INDEX(Material!$I:$I,StartRow+25), 0 ), MATCH( G15, INDEX(Material!$I:$V,StartRow+1,0), 0 ) ) ), XLOOKUP(C15,Material!$A:$A,Material!$D:$D) ), "")} | U15: {=IFERROR( IF( D15="R-Flashing", XLOOKUP(CEILING(E15*1000,50),Material!I:I,Material!X:X), XLOOKUP(C15,Material!A:A,Material!E:E) ), "" )}
